Workbook

Sheet Timetable
A2: Cybersecurity bootcamp timetable
A3: 5 October–25 December 2026. Devotion: 8–8:30 a.m. Standup: 8:30–8:45 a.m. Lessons: 8:45 a.m.–5 p.m. Lunch: 1–2 p.m.
A4: Proposed trainer groups follow the outline; daily allocation is pending. TBC = trainer to be confirmed.
A5: Group activity or guided study: 30 minutes daily. Practical/lab: 2–4 p.m. Projects: assignments outside class. All weekdays are scheduled.
A7: Date | B7: Day | C7: Session / activity | D7: Time | E7: Course / practical work | F7: Trainer(s) — proposed
A8: Week 1: Foundations and professional orientation
A9: 46300 | B9: Monday | C9: Morning devotion | D9: =TEXT('Course Outline'!J25,"h:mm AM/PM")&" – "&TEXT('Course Outline'!K25,"h:mm AM/PM") -> 8:00 AM – 8:30 AM
C10: Daily standup | D10: =TEXT('Course Outline'!J26,"h:mm AM/PM")&" – "&TEXT('Course Outline'!K26,"h:mm AM/PM") -> 8:30 AM – 8:45 AM | E10: Attendance, daily goals and team progress
C11: Theory / professional skills | D11: =TEXT('Course Outline'!J27,"h:mm AM/PM")&" – "&TEXT('Course Outline'!K27,"h:mm AM/PM") -> 8:45 AM – 10:20 AM | E11: Kick-off: welcome, programme overview and expectations | F11: Stanley K. Dankyira, Diana van der Stelt
C12: Short break | D12: =TEXT('Course Outline'!J28,"h:mm AM/PM")&" – "&TEXT('Course Outline'!K28,"h:mm AM/PM") -> 10:20 AM – 10:30 AM | E12: 10-minute refreshment / stretch break
C13: Professional orientation | D13: =TEXT('Course Outline'!J29,"h:mm AM/PM")&" – "&TEXT('Course Outline'!K29,"h:mm AM/PM") -> 10:30 AM – 12:30 PM | E13: Getting to know Maxim Nyansa: mission, people and ways of working | F13: Stanley K. Dankyira, Diana van der Stelt
C14: Group activity | D14: =TEXT('Course Outline'!J30,"h:mm AM/PM")&" – "&TEXT('Course Outline'!K30,"h:mm AM/PM") -> 12:30 PM – 1:00 PM | E14: Icebreaker and introductions | F14: Stanley K. Dankyira, Diana van der Stelt
C15: Lunch break | D15: =TEXT('Course Outline'!J31,"h:mm AM/PM")&" – "&TEXT('Course Outline'!K31,"h:mm AM/PM") -> 1:00 PM – 2:00 PM | E15: LUNCH BREAK
C16: Practical / workshop | D16: =TEXT('Course Outline'!J32,"h:mm AM/PM")&" – "&TEXT('Course Outline'!K32,"h:mm AM/PM") -> 2:00 PM – 4:00 PM | E16: Onboarding: accounts, devices, learning platforms and house rules 10-minute break: 3:20–3:30 p.m. | F16: Stanley K. Dankyira, Diana van der Stelt
C17: Theory / discussion | D17: =TEXT('Course Outline'!J33,"h:mm AM/PM")&" – "&TEXT('Course Outline'!K33,"h:mm AM/PM") -> 4:00 PM – 5:00 PM | E17: Questions, reflections and review of day one | F17: Stanley K. Dankyira, Diana van der Stelt
A18: 46301 | B18: Tuesday | C18: Morning devotion | D18: =TEXT('Course Outline'!J25,"h:mm AM/PM")&" – "&TEXT('Course Outline'!K25,"h:mm AM/PM") -> 8:00 AM – 8:30 AM | E18: Morning devotion
C19: Daily standup | D19: =TEXT('Course Outline'!J26,"h:mm AM/PM")&" – "&TEXT('Course Outline'!K26,"h:mm AM/PM") -> 8:30 AM – 8:45 AM | E19: Attendance, daily goals and team progress
C20: Theory / professional skills | D20: =TEXT('Course Outline'!J27,"h:mm AM/PM")&" – "&TEXT('Course Outline'!K27,"h:mm AM/PM") -> 8:45 AM – 10:20 AM | E20: Team formation: how effective teams work; team roles | F20: Stanley K. Dankyira, Diana van der Stelt
C21: Short break | D21: =TEXT('Course Outline'!J28,"h:mm AM/PM")&" – "&TEXT('Course Outline'!K28,"h:mm AM/PM") -> 10:20 AM – 10:30 AM | E21: 10-minute refreshment / stretch break
C22: Professional orientation | D22: =TEXT('Course Outline'!J29,"h:mm AM/PM")&" – "&TEXT('Course Outline'!K29,"h:mm AM/PM") -> 10:30 AM – 12:30 PM | E22: Team formation workshop: strengths, roles and communication | F22: Stanley K. Dankyira, Diana van der Stelt
C23: Group activity | D23: =TEXT('Course Outline'!J30,"h:mm AM/PM")&" – "&TEXT('Course Outline'!K30,"h:mm AM/PM") -> 12:30 PM – 1:00 PM | E23: Team-building activity | F23: Stanley K. Dankyira, Diana van der Stelt
C24: Lunch break | D24: =TEXT('Course Outline'!J31,"h:mm AM/PM")&" – "&TEXT('Course Outline'!K31,"h:mm AM/PM") -> 1:00 PM – 2:00 PM | E24: LUNCH BREAK
C25: Practical / workshop | D25: =TEXT('Course Outline'!J32,"h:mm AM/PM")&" – "&TEXT('Course Outline'!K32,"h:mm AM/PM") -> 2:00 PM – 4:00 PM | E25: Form project teams and agree team roles 10-minute break: 3:20–3:30 p.m. | F25: Stanley K. Dankyira, Diana van der Stelt
C26: Theory / discussion | D26: =TEXT('Course Outline'!J33,"h:mm AM/PM")&" – "&TEXT('Course Outline'!K33,"h:mm AM/PM") -> 4:00 PM – 5:00 PM | E26: Team check-in and review | F26: Stanley K. Dankyira, Diana van der Stelt
A27: 46302 | B27: Wednesday | C27: Morning devotion | D27: =TEXT('Course Outline'!J25,"h:mm AM/PM")&" – "&TEXT('Course Outline'!K25,"h:mm AM/PM") -> 8:00 AM – 8:30 AM | E27: Morning devotion
C28: Daily standup | D28: =TEXT('Course Outline'!J26,"h:mm AM/PM")&" – "&TEXT('Course Outline'!K26,"h:mm AM/PM") -> 8:30 AM – 8:45 AM | E28: Attendance, daily goals and team progress
C29: Theory / professional skills | D29: =TEXT('Course Outline'!J27,"h:mm AM/PM")&" – "&TEXT('Course Outline'!K27,"h:mm AM/PM") -> 8:45 AM – 10:20 AM | E29: Learning agreement: expectations, commitments and code of conduct | F29: Stanley K. Dankyira, Diana van der Stelt
C30: Short break | D30: =TEXT('Course Outline'!J28,"h:mm AM/PM")&" – "&TEXT('Course Outline'!K28,"h:mm AM/PM") -> 10:20 AM – 10:30 AM | E30: 10-minute refreshment / stretch break
D31: =TEXT('Course Outline'!J29,"h:mm AM/PM")&" – "&TEXT('Course Outline'!K29,"h:mm AM/PM") -> 10:30 AM – 12:30 PM | E31: Inter-School Rebotics Competitions: Google Office | F31: Maxim Nyansa Team
D32: =TEXT('Course Outline'!J30,"h:mm AM/PM")&" – "&TEXT('Course Outline'!K30,"h:mm AM/PM") -> 12:30 PM – 1:00 PM | E32: Inter-School Rebotics Competitions: Google Office | F32: Maxim Nyansa Team
C33: Lunch break | D33: =TEXT('Course Outline'!J31,"h:mm AM/PM")&" – "&TEXT('Course Outline'!K31,"h:mm AM/PM") -> 1:00 PM – 2:00 PM | E33: LUNCH BREAK
D34: =TEXT('Course Outline'!J32,"h:mm AM/PM")&" – "&TEXT('Course Outline'!K32,"h:mm AM/PM") -> 2:00 PM – 4:00 PM | E34: Inter-School Rebotics Competitions: Google Office | F34: Maxim Nyansa Team
D35: =TEXT('Course Outline'!J33,"h:mm AM/PM")&" – "&TEXT('Course Outline'!K33,"h:mm AM/PM") -> 4:00 PM – 5:00 PM | E35: Inter-School Rebotics Competitions: Google Office | F35: Maxim Nyansa Team
A36: 46303 | B36: Thursday | C36: Morning devotion | D36: =TEXT('Course Outline'!J25,"h:mm AM/PM")&" – "&TEXT('Course Outline'!K25,"h:mm AM/PM") -> 8:00 AM – 8:30 AM | E36: Morning devotion
C37: Daily standup | D37: =TEXT('Course Outline'!J26,"h:mm AM/PM")&" – "&TEXT('Course Outline'!K26,"h:mm AM/PM") -> 8:30 AM – 8:45 AM | E37: Attendance, daily goals and team progress
C38: Technical theory | D38: =TEXT('Course Outline'!J27,"h:mm AM/PM")&" – "&TEXT('Course Outline'!K27,"h:mm AM/PM") -> 8:45 AM – 10:20 AM | E38: CIA triad: confidentiality, integrity and availability | F38: Martha
C39: Short break | D39: =TEXT('Course Outline'!J28,"h:mm AM/PM")&" – "&TEXT('Course Outline'!K28,"h:mm AM/PM") -> 10:20 AM – 10:30 AM | E39: 10-minute refreshment / stretch break
C40: Technical theory | D40: =TEXT('Course Outline'!J29,"h:mm AM/PM")&" – "&TEXT('Course Outline'!K29,"h:mm AM/PM") -> 10:30 AM – 12:30 PM | E40: Threats, vulnerabilities and security controls — concepts, cases and key terms | F40: Martha
C41: Group activity | D41: =TEXT('Course Outline'!J30,"h:mm AM/PM")&" – "&TEXT('Course Outline'!K30,"h:mm AM/PM") -> 12:30 PM – 1:00 PM | E41: Threats, vulnerabilities and controls — group discussion and knowledge check | F41: Martha
C42: Lunch break | D42: =TEXT('Course Outline'!J31,"h:mm AM/PM")&" – "&TEXT('Course Outline'!K31,"h:mm AM/PM") -> 1:00 PM – 2:00 PM | E42: LUNCH BREAK
...

Sheet Course Outline
A1: Cybersecurity Bootcamp Outline — 12 Weeks
A2: Start date: Monday, 5 October 2026 | 12-week programme | Trainer fields are ready for allocation
A3: Week | B3: Starting Date | C3: General Professionalism Courses | D3: Trainer(s) | E3: Cybersecurity Training Content | F3: Trainer(s) | G3: Weekly Practical / Deliverable
A4: Block 1: Foundations & Secure Systems | C4: Professional Foundation | E4: Cybersecurity Foundations
A5: Week 1 | B5: 46300 | C5: Kick-off Getting to know Maxim Nyansa Team formation and learning agreement | D5: Stanley K. Dankyira, Diana van der Stelt | E5: Cybersecurity foundations: CIA triad, risk, threat, vulnerability and security controls Cybersecurity careers, legal boundaries and professional ethics | F5: Martha, Erik Schneider, Sanders | G5: Personal learning plan Team project groups and project charter
A6: Week 2 | B6: 46307 | C6: Personal development and time management Study routines for technical learning | D6: Diana van der Stelt | E6: TCP/IP networking: nodes, connections and IPv4/IPv6 addressing OSI and TCP/IP models; common protocols, ports and packet flow | F6: Othniel, David Davor, Alfred Kumah | G6: Network map and protocol reference sheet Basic addressing / packet-flow practice
A7: Week 3 | B7: 46314 | C7: Professional communication and report writing Documenting technical findings | D7: Precious, Stanley | E7: Computer systems: architecture and operating systems System vulnerabilities and security measures: patching, hardening, backups, logging and endpoint protection | F7: Ken, David Davor, Alfred Kumah | G7: Secure workstation baseline checklist System hardening report
A8: Week 4 | B8: 46321 | C8: Digital ethics, data protection and responsible conduct | D8: Frank Donkor, Arnold | E8: Security Management (incl Risk Management, ISO 27k, Governance/Compliance/Regulations, and a Crisis Management Table Top | F8: Louis van Dyk, Ruud van den Einden, Sanders | G8: Risk Assessment Sprint Spot the Gap Crisis Simulation (tabletop) Role playing Audit
A9: Block 2: Applications, Data & Cryptography | C9: Professional Practice | E9: Protecting Applications and Information
A10: Week 5 | B10: 46328 | C10: Time Management, Working with roles and deadlines | D10: Diana van der Stelt | E10: Applications: software development life cycle (SDLC), secure development principles and application security Web risks awareness: insecure input, XSS and insecure configuration | F10: Ken, David Davor, Alfred Kumah | G10: Secure code / application review exercise in a safe training sandbox
A11: Week 6 | B11: 46335 | C11: Leadership & Financial Management | D11: Bishop Seth Aryitey | E11: Databases: models, DBMS functions, data integrity and access controls Database security risks and countermeasures, including injection awareness and secure handling of sensitive data | F11: Othniel | G11: Database security checklist Role/permission matrix and recovery plan
A12: Week 7 | B12: 46342 | C12: Problem-solving and critical-thinking methods | D12: Othniel | E12: Cryptography I: symmetric and asymmetric encryption, algorithms and standards Key management, encryption strength, data at rest and data in transit Cryptography II: hashing, digital signatures, PKI and digital certificates SSL/TLS, IPSec and secure communication use cases | F12: Othniel, Tom Tervoort, Dr. Antwi Bosiako, Alfred Kumah | G12: Encryption and hashing practice Short key-management policy Certificate inspection exercise Secure communications explanation / mini demo
A13: Week 8 | B13: 46349 | C13: Cybersecurity careers, CV and LinkedIn profile development | E13: Identity and access management I: identification vs authentication, MFA, biometrics, password management and single sign-on & Identity and access management II: authorization, need-to-know, least privilege and separation of duties RBAC, ABAC, OAuth 2.0 and OpenID Connect | F13: Adeodata, Alfred Kumah | G13: Password and MFA policy IAM user-journey exercise Access-control matrix Least-privilege improvement proposal
A14: Block 3: Identity, Cloud, Threats & Capstone | C14: Career Readiness | E14: Security Operations and Defence
A15: Week 9 | B15: 46356 | C15: Interview preparation and portfolio-building | D15: George Edward Plange | E15: Cloud computing: public, private and hybrid deployments SaaS, PaaS, IaaS, SECaaS and IDaaS; cloud risks, shared responsibility and controls | F15: Ken, George Plange, David Davor | G15: Cloud security checklist Risk register for a selected cloud service
A16: Week 10 | B16: 46363 | C16: Consultancy skills and client communication | D16: To be confirmed | E16: Exploiting vulnerabilities: attack categories, threat actors and common tools Reconnaissance, scanning, phishing, malware and social-engineering awareness — restricted to authorised training environments | F16: Martha, Yannick Fournel, Alfred Kumah | G16: Authorised vulnerability-assessment report Prioritised remediation recommendations
A17: Week 11 | B17: 46370 | C17: Presentation skills and capstone documentation | D17: Jair Santanna, Arnold | E17: AI & Cyber: learn-by-doing automations using Artificial Intelligence (i.e., large language models) revisiting most of the cybersecurity areas in the program (1. Governance and Compliance, 2. Defense, 3. Offense, 4. Incident response, 5. Behavior, and 6. Threat intelligence). Learn to critically analyze what (AI) tools are best for what sorts of tasks and why the human-in-the-loop is needed | F17: Jair Santanna,Alfred Kumah, Sanders | G17: Automate compliance/audit checks and reporting Automate SOC alarms and incident handling (covering the cyber kill chain) Automate threat intelligence gathering Automate offensive tests
A18: Week 12 | B18: 46377 | C18: Final presentations, reflection and professional next steps | D18: All | E18: Incident-response basics, security monitoring and review Integrated exam revision and cybersecurity mini-project presentations | F18: Arnold/Ken, Sanders | G18: Capstone presentation 40-question mock assessment and personal next-step plan
A20: Source: Cybersecurity Bootcamp Outline 2026 Version 1.1.xlsx, Cybersecurity Outline sheet.
A22: Timetable starts Monday, 5 October 2026.
I24: Daily session | J24: Start | K24: End
I25: Morning devotion | J25: 0.33333333 | K25: 0.35416667
I26: Daily standup | J26: 0.35416667 | K26: 0.36458333
I27: Theory / professional skills | J27: 0.36458333 | K27: 0.43055556
I28: Short break | J28: 0.43055556 | K28: 0.4375
I29: Technical theory | J29: 0.4375 | K29: 0.52083333
I30: Group activity or guided study | J30: 0.52083333 | K30: 0.54166667
I31: Lunch break | J31: 0.54166667 | K31: 0.58333333
I32: Practical / lab | J32: 0.58333333 | K32: 0.66666667
I33: Theory / discussion | J33: 0.66666667 | K33: 0.70833333
I38: Thursday / Friday session | J38: Start | K38: End
I39: Practical / lab | J39: 0.58333333 | K39: 0.66666667
I40: Madam Diana | J40: 0.66666667 | K40: 0.70833333
